INFO     delete_data:delete_data.py:213 未查询到物料BOM数据，跳过删除操作
INFO     delete_data:delete_data.py:378 物料BOM数据不存在或已被清理，跳过删除
WARNING  get_token:get_token.py:51 Token验证请求失败: HTTPConnectionPool(host='192.168.0.135', port=8282): Max retries exceeded with url: /MaterialInfoApi/GetMaterialInfoAutoQueryDatas (Caused by NewConnectionError('<urllib3.connection.HTTPConnection object at 0x0000026366BCDB50>: Failed to establish a new connection: [WinError 10061] 由于目标计算机积极拒绝，无法连接。'))，但继续使用获取到的token
ERROR    ProcessRelated:production_process.py:78 请求发生错误: HTTPConnectionPool(host='192.168.0.135', port=8282): Max retries exceeded with url: /ProductRouteApi/GetProcessInfoAutoQueryDatas (Caused by NewConnectionError('<urllib3.connection.HTTPConnection object at 0x0000026367BB10D0>: Failed to establish a new connection: [WinError 10061] 由于目标计算机积极拒绝，无法连接。'))，请求 URL: http://192.168.0.135:8282/ProductRouteApi/GetProcessInfoAutoQueryDatas，请求头: {'authorization': 'Bearer eyJhbGciOiJIUzI1NiIsInR5cCI6IkpXVCJ9.eyJVc2VySWQiOiIxNTAiLCJVc2VyQ29kZSI6IkRlbW9BZG1pbiIsIlVzZXJOYW1lIjoiRGVtb0FkbWluIiwiVXNlclR5cGUiOiIxIiwiQ29tcGFueUNvZGUiOiIwMDAwMCIsIkZhY3RvcnlDb2RlIjoiMDAwMDAuMDAwMDEiLCJJcCI6IjE5Mi4xNjguODIuMjA0IiwiT3JnYW5pemF0aW9uU3RydWN0dXJlQ29kZSI6IjAwMDAwLjAwMDAxLjAwMDAzIiwiZXhwIjoxNzUyNDU5ODc5LCJpc3MiOiJSaC5NZXMiLCJhdWQiOiJSaC5NZXMuU2VydmljZXMifQ.X2r_l-Lfd4dIQlIA7HJoEPMaibvBfB3Yz0iqX2phEv8'}，请求体: {'ProcessCode': 'Automation01', 'ProcessName': '', 'PageSize': 10, 'PageIndex': 1, 'CompanyCode': '00000', 'FactoryCode': '00000.00001'}
ERROR    delete_data:delete_data.py:108 工序查询接口返回空响应
ERROR    delete_data:delete_data.py:382 工序数据清理失败: 工序查询失败: 接口返回空响应
Traceback (most recent call last):
  File "D:\apiAutomationRH\Toolbox\delete_data.py", line 376, in clean_related_data
    result = delete_func()
             ^^^^^^^^^^^^^
  File "D:\apiAutomationRH\Toolbox\delete_data.py", line 109, in _delete_process_data
    raise RuntimeError("工序查询失败: 接口返回空响应")
RuntimeError: 工序查询失败: 接口返回空响应
WARNING  get_token:get_token.py:51 Token验证请求失败: HTTPConnectionPool(host='192.168.0.135', port=8282): Max retries exceeded with url: /MaterialInfoApi/GetMaterialInfoAutoQueryDatas (Caused by NewConnectionError('<urllib3.connection.HTTPConnection object at 0x0000026366BD5450>: Failed to establish a new connection: [WinError 10061] 由于目标计算机积极拒绝，无法连接。'))，但继续使用获取到的token
ERROR    ProcessRelated:production_process.py:145 请求发生错误: HTTPConnectionPool(host='192.168.0.135', port=8282): Max retries exceeded with url: /ProductRouteApi/GetProcessRoutingAutoQueryDatas (Caused by NewConnectionError('<urllib3.connection.HTTPConnection object at 0x0000026366BC31D0>: Failed to establish a new connection: [WinError 10061] 由于目标计算机积极拒绝，无法连接。'))，请求 URL: http://192.168.0.135:8282/ProductRouteApi/GetProcessRoutingAutoQueryDatas，请求头: {'authorization': 'Bearer eyJhbGciOiJIUzI1NiIsInR5cCI6IkpXVCJ9.eyJVc2VySWQiOiIxNTAiLCJVc2VyQ29kZSI6IkRlbW9BZG1pbiIsIlVzZXJOYW1lIjoiRGVtb0FkbWluIiwiVXNlclR5cGUiOiIxIiwiQ29tcGFueUNvZGUiOiIwMDAwMCIsIkZhY3RvcnlDb2RlIjoiMDAwMDAuMDAwMDEiLCJJcCI6IjE5Mi4xNjguODIuMjA0IiwiT3JnYW5pemF0aW9uU3RydWN0dXJlQ29kZSI6IjAwMDAwLjAwMDAxLjAwMDAzIiwiZXhwIjoxNzUyNDU5ODgzLCJpc3MiOiJSaC5NZXMiLCJhdWQiOiJSaC5NZXMuU2VydmljZXMifQ.K3OSwp4-Sx0wM5E-0bu9ECSmAMHSV8l99U4qS7xZpgU'}，请求体: {'ProcessRoutingCode': 'Automation01', 'IsPaged': True, 'PageSize': 10, 'PageIndex': 1, 'CompanyCode': '00000', 'FactoryCode': '00000.00001'}
ERROR    delete_data:delete_data.py:141 工艺路线查询接口返回空响应
ERROR    delete_data:delete_data.py:382 工艺路线数据清理失败: 工艺路线查询失败: 接口返回空响应
Traceback (most recent call last):
  File "D:\apiAutomationRH\Toolbox\delete_data.py", line 376, in clean_related_data
    result = delete_func()
             ^^^^^^^^^^^^^
  File "D:\apiAutomationRH\Toolbox\delete_data.py", line 142, in _delete_process_routing_data
    raise RuntimeError("工艺路线查询失败: 接口返回空响应")
RuntimeError: 工艺路线查询失败: 接口返回空响应
WARNING  get_token:get_token.py:51 Token验证请求失败: HTTPConnectionPool(host='192.168.0.135', port=8282): Max retries exceeded with url: /MaterialInfoApi/GetMaterialInfoAutoQueryDatas (Caused by NewConnectionError('<urllib3.connection.HTTPConnection object at 0x0000026367BD5750>: Failed to establish a new connection: [WinError 10061] 由于目标计算机积极拒绝，无法连接。'))，但继续使用获取到的token
ERROR    ProcessRelated:production_process.py:196 请求发生错误: HTTPConnectionPool(host='192.168.0.135', port=8282): Max retries exceeded with url: /ProductRouteApi/GetProductProcessRouteAutoQueryDatas (Caused by NewConnectionError('<urllib3.connection.HTTPConnection object at 0x0000026367BD7FD0>: Failed to establish a new connection: [WinError 10061] 由于目标计算机积极拒绝，无法连接。'))，请求 URL: http://192.168.0.135:8282/ProductRouteApi/GetProductProcessRouteAutoQueryDatas，请求头: {'authorization': 'Bearer eyJhbGciOiJIUzI1NiIsInR5cCI6IkpXVCJ9.eyJVc2VySWQiOiIxNTAiLCJVc2VyQ29kZSI6IkRlbW9BZG1pbiIsIlVzZXJOYW1lIjoiRGVtb0FkbWluIiwiVXNlclR5cGUiOiIxIiwiQ29tcGFueUNvZGUiOiIwMDAwMCIsIkZhY3RvcnlDb2RlIjoiMDAwMDAuMDAwMDEiLCJJcCI6IjE5Mi4xNjguODIuMjA0IiwiT3JnYW5pemF0aW9uU3RydWN0dXJlQ29kZSI6IjAwMDAwLjAwMDAxLjAwMDAzIiwiZXhwIjoxNzUyNDU5ODg3LCJpc3MiOiJSaC5NZXMiLCJhdWQiOiJSaC5NZXMuU2VydmljZXMifQ.02Q0jGaTIR_EYRIxfxex1TWG7VFEJt2uaj1Uo42rFW4'}，请求体: {'ProductCode': 'Automation01', 'IsPaged': True, 'PageSize': 10, 'PageIndex': 1, 'CompanyCode': '00000', 'FactoryCode': '00000.00001'}
ERROR    delete_data:delete_data.py:174 产品工艺路线查询接口返回空响应
ERROR    delete_data:delete_data.py:382 产品工艺路线数据清理失败: 产品工艺路线查询失败: 接口返回空响应
Traceback (most recent call last):
  File "D:\apiAutomationRH\Toolbox\delete_data.py", line 376, in clean_related_data
    result = delete_func()
             ^^^^^^^^^^^^^
  File "D:\apiAutomationRH\Toolbox\delete_data.py", line 175, in _delete_product_process_route_data
    raise RuntimeError("产品工艺路线查询失败: 接口返回空响应")
RuntimeError: 产品工艺路线查询失败: 接口返回空响应
WARNING  get_token:get_token.py:51 Token验证请求失败: HTTPConnectionPool(host='192.168.0.135', port=8282): Max retries exceeded with url: /MaterialInfoApi/GetMaterialInfoAutoQueryDatas (Caused by NewConnectionError('<urllib3.connection.HTTPConnection object at 0x0000026367BD5050>: Failed to establish a new connection: [WinError 10061] 由于目标计算机积极拒绝，无法连接。'))，但继续使用获取到的token
ERROR    ProductMaterials:product_materials.py:97 请求发生错误: HTTPConnectionPool(host='192.168.0.135', port=8282): Max retries exceeded with url: /MaterialInfoApi/GetMaterialInfoAutoQueryDatas (Caused by NewConnectionError('<urllib3.connection.HTTPConnection object at 0x0000026366BD5250>: Failed to establish a new connection: [WinError 10061] 由于目标计算机积极拒绝，无法连接。'))，请求 URL: http://192.168.0.135:8282/MaterialInfoApi/GetMaterialInfoAutoQueryDatas，请求头: {'authorization': 'Bearer eyJhbGciOiJIUzI1NiIsInR5cCI6IkpXVCJ9.eyJVc2VySWQiOiIxNTAiLCJVc2VyQ29kZSI6IkRlbW9BZG1pbiIsIlVzZXJOYW1lIjoiRGVtb0FkbWluIiwiVXNlclR5cGUiOiIxIiwiQ29tcGFueUNvZGUiOiIwMDAwMCIsIkZhY3RvcnlDb2RlIjoiMDAwMDAuMDAwMDEiLCJJcCI6IjE5Mi4xNjguODIuMjA0IiwiT3JnYW5pemF0aW9uU3RydWN0dXJlQ29kZSI6IjAwMDAwLjAwMDAxLjAwMDAzIiwiZXhwIjoxNzUyNDU5ODkyLCJpc3MiOiJSaC5NZXMiLCJhdWQiOiJSaC5NZXMuU2VydmljZXMifQ.EEVjcZ3dfB1OimNaqm1sn4w-pirc0mmNXlXnbJ4NIZY'}，请求体: {'MaterialCode': 'Automation01'}
ERROR    delete_data:delete_data.py:75 物料查询接口返回空响应
ERROR    delete_data:delete_data.py:382 物料数据清理失败: 物料查询失败: 接口返回空响应
Traceback (most recent call last):
  File "D:\apiAutomationRH\Toolbox\delete_data.py", line 376, in clean_related_data
    result = delete_func()
             ^^^^^^^^^^^^^
  File "D:\apiAutomationRH\Toolbox\delete_data.py", line 76, in _delete_material_data
    raise RuntimeError("物料查询失败: 接口返回空响应")
RuntimeError: 物料查询失败: 接口返回空响应
WARNING  get_token:get_token.py:51 Token验证请求失败: HTTPConnectionPool(host='192.168.0.135', port=8282): Max retries exceeded with url: /MaterialInfoApi/GetMaterialInfoAutoQueryDatas (Caused by NewConnectionError('<urllib3.connection.HTTPConnection object at 0x0000026366B74A90>: Failed to establish a new connection: [WinError 10061] 由于目标计算机积极拒绝，无法连接。'))，但继续使用获取到的token
ERROR    EquipmentLedgerManagement:equipment_ledger_management.py:65 请求发生错误: HTTPConnectionPool(host='192.168.0.135', port=8282): Max retries exceeded with url: /EquipmentLedgerApi/GetEquipmentLedgerAutoQueryDatas (Caused by NewConnectionError('<urllib3.connection.HTTPConnection object at 0x0000026366B10190>: Failed to establish a new connection: [WinError 10061] 由于目标计算机积极拒绝，无法连接。'))，请求 URL: http://192.168.0.135:8282/EquipmentLedgerApi/GetEquipmentLedgerAutoQueryDatas，请求头: {'authorization': 'Bearer eyJhbGciOiJIUzI1NiIsInR5cCI6IkpXVCJ9.eyJVc2VySWQiOiIxNTAiLCJVc2VyQ29kZSI6IkRlbW9BZG1pbiIsIlVzZXJOYW1lIjoiRGVtb0FkbWluIiwiVXNlclR5cGUiOiIxIiwiQ29tcGFueUNvZGUiOiIwMDAwMCIsIkZhY3RvcnlDb2RlIjoiMDAwMDAuMDAwMDEiLCJJcCI6IjE5Mi4xNjguODIuMjA0IiwiT3JnYW5pemF0aW9uU3RydWN0dXJlQ29kZSI6IjAwMDAwLjAwMDAxLjAwMDAzIiwiZXhwIjoxNzUyNDU5ODk3LCJpc3MiOiJSaC5NZXMiLCJhdWQiOiJSaC5NZXMuU2VydmljZXMifQ.Ur66_aTvQ1E_YrubF2J2azEdI084SgEZz60pQh2fdYc'}，请求体: {'EquipmentCode': 'Automation01', 'EquipmentName': '自动化测试设备', 'PageSize': 10, 'PageIndex': 1, 'CompanyCode': '00000', 'FactoryCode': '00000.00001'}
ERROR    delete_data:delete_data.py:267 网络请求异常: HTTPConnectionPool(host='192.168.0.135', port=8282): Max retries exceeded with url: /EquipmentLedgerApi/GetEquipmentLedgerAutoQueryDatas (Caused by NewConnectionError('<urllib3.connection.HTTPConnection object at 0x0000026366B10190>: Failed to establish a new connection: [WinError 10061] 由于目标计算机积极拒绝，无法连接。'))
ERROR    delete_data:delete_data.py:382 设备台账数据清理失败: HTTPConnectionPool(host='192.168.0.135', port=8282): Max retries exceeded with url: /EquipmentLedgerApi/GetEquipmentLedgerAutoQueryDatas (Caused by NewConnectionError('<urllib3.connection.HTTPConnection object at 0x0000026366B10190>: Failed to establish a new connection: [WinError 10061] 由于目标计算机积极拒绝，无法连接。'))
Traceback (most recent call last):
  File "D:\apiAutomationRH\.venv\Lib\site-packages\urllib3\connection.py", line 198, in _new_conn
    sock = connection.create_connection(
           ^^^^^^^^^^^^^^^^^^^^^^^^^^^^^
  File "D:\apiAutomationRH\.venv\Lib\site-packages\urllib3\util\connection.py", line 85, in create_connection
    raise err
  File "D:\apiAutomationRH\.venv\Lib\site-packages\urllib3\util\connection.py", line 73, in create_connection
    sock.connect(sa)
ConnectionRefusedError: [WinError 10061] 由于目标计算机积极拒绝，无法连接。

The above exception was the direct cause of the following exception:

Traceback (most recent call last):
  File "D:\apiAutomationRH\.venv\Lib\site-packages\urllib3\connectionpool.py", line 787, in urlopen
    response = self._make_request(
               ^^^^^^^^^^^^^^^^^^^
  File "D:\apiAutomationRH\.venv\Lib\site-packages\urllib3\connectionpool.py", line 493, in _make_request
    conn.request(
  File "D:\apiAutomationRH\.venv\Lib\site-packages\urllib3\connection.py", line 494, in request
    self.endheaders()
  File "D:\python\Lib\http\client.py", line 1281, in endheaders
    self._send_output(message_body, encode_chunked=encode_chunked)
  File "D:\python\Lib\http\client.py", line 1041, in _send_output
    self.send(msg)
  File "D:\python\Lib\http\client.py", line 979, in send
    self.connect()
  File "D:\apiAutomationRH\.venv\Lib\site-packages\urllib3\connection.py", line 325, in connect
    self.sock = self._new_conn()
                ^^^^^^^^^^^^^^^^
  File "D:\apiAutomationRH\.venv\Lib\site-packages\urllib3\connection.py", line 213, in _new_conn
    raise NewConnectionError(
urllib3.exceptions.NewConnectionError: <urllib3.connection.HTTPConnection object at 0x0000026366B10190>: Failed to establish a new connection: [WinError 10061] 由于目标计算机积极拒绝，无法连接。

The above exception was the direct cause of the following exception:

Traceback (most recent call last):
  File "D:\apiAutomationRH\.venv\Lib\site-packages\requests\adapters.py", line 667, in send
    resp = conn.urlopen(
           ^^^^^^^^^^^^^
  File "D:\apiAutomationRH\.venv\Lib\site-packages\urllib3\connectionpool.py", line 841, in urlopen
    retries = retries.increment(
              ^^^^^^^^^^^^^^^^^^
  File "D:\apiAutomationRH\.venv\Lib\site-packages\urllib3\util\retry.py", line 519, in increment
    raise MaxRetryError(_pool, url, reason) from reason  # type: ignore[arg-type]
    ^^^^^^^^^^^^^^^^^^^^^^^^^^^^^^^^^^^^^^^^^^^^^^^^^^^
urllib3.exceptions.MaxRetryError: HTTPConnectionPool(host='192.168.0.135', port=8282): Max retries exceeded with url: /EquipmentLedgerApi/GetEquipmentLedgerAutoQueryDatas (Caused by NewConnectionError('<urllib3.connection.HTTPConnection object at 0x0000026366B10190>: Failed to establish a new connection: [WinError 10061] 由于目标计算机积极拒绝，无法连接。'))

During handling of the above exception, another exception occurred:

Traceback (most recent call last):
  File "D:\apiAutomationRH\Toolbox\delete_data.py", line 376, in clean_related_data
    result = delete_func()
             ^^^^^^^^^^^^^
  File "D:\apiAutomationRH\Toolbox\delete_data.py", line 240, in _delete_equipment_ledger_data
    query_response = equipment_ledger.getEquipmentLedgerAutoQueryDatas()
                     ^^^^^^^^^^^^^^^^^^^^^^^^^^^^^^^^^^^^^^^^^^^^^^^^^^^
  File "D:\apiAutomationRH\Business\mom_admin\equipment_management\equipment_ledger_management.py", line 66, in getEquipmentLedgerAutoQueryDatas
    raise e
  File "D:\apiAutomationRH\Business\mom_admin\equipment_management\equipment_ledger_management.py", line 61, in getEquipmentLedgerAutoQueryDatas
    response = requests.post(url=urlGetEquipmentLedgerAutoQueryDatas, headers=self.headers, json=uploads)
               ^^^^^^^^^^^^^^^^^^^^^^^^^^^^^^^^^^^^^^^^^^^^^^^^^^^^^^^^^^^^^^^^^^^^^^^^^^^^^^^^^^^^^^^^^^
  File "D:\apiAutomationRH\.venv\Lib\site-packages\requests\api.py", line 115, in post
    return request("post", url, data=data, json=json, **kwargs)
           ^^^^^^^^^^^^^^^^^^^^^^^^^^^^^^^^^^^^^^^^^^^^^^^^^^^^
  File "D:\apiAutomationRH\.venv\Lib\site-packages\requests\api.py", line 59, in request
    return session.request(method=method, url=url, **kwargs)
           ^^^^^^^^^^^^^^^^^^^^^^^^^^^^^^^^^^^^^^^^^^^^^^^^^
  File "D:\apiAutomationRH\.venv\Lib\site-packages\requests\sessions.py", line 589, in request
    resp = self.send(prep, **send_kwargs)
           ^^^^^^^^^^^^^^^^^^^^^^^^^^^^^^
  File "D:\apiAutomationRH\.venv\Lib\site-packages\requests\sessions.py", line 703, in send
    r = adapter.send(request, **kwargs)
        ^^^^^^^^^^^^^^^^^^^^^^^^^^^^^^^
  File "D:\apiAutomationRH\.venv\Lib\site-packages\requests\adapters.py", line 700, in send
    raise ConnectionError(e, request=request)
requests.exceptions.ConnectionError: HTTPConnectionPool(host='192.168.0.135', port=8282): Max retries exceeded with url: /EquipmentLedgerApi/GetEquipmentLedgerAutoQueryDatas (Caused by NewConnectionError('<urllib3.connection.HTTPConnection object at 0x0000026366B10190>: Failed to establish a new connection: [WinError 10061] 由于目标计算机积极拒绝，无法连接。'))
WARNING  get_token:get_token.py:51 Token验证请求失败: HTTPConnectionPool(host='192.168.0.135', port=8282): Max retries exceeded with url: /MaterialInfoApi/GetMaterialInfoAutoQueryDatas (Caused by NewConnectionError('<urllib3.connection.HTTPConnection object at 0x0000026366B00750>: Failed to establish a new connection: [WinError 10061] 由于目标计算机积极拒绝，无法连接。'))，但继续使用获取到的token
ERROR    FactoryModel:factory_model.py:163 请求发生错误: HTTPConnectionPool(host='192.168.0.135', port=8282): Max retries exceeded with url: /ProductionLineApi/GetAllProductionLineAutoQueryDatas (Caused by NewConnectionError('<urllib3.connection.HTTPConnection object at 0x0000026367BDD490>: Failed to establish a new connection: [WinError 10061] 由于目标计算机积极拒绝，无法连接。'))，请求 URL: http://192.168.0.135:8282/ProductionLineApi/GetAllProductionLineAutoQueryDatas，请求头: {'authorization': 'Bearer eyJhbGciOiJIUzI1NiIsInR5cCI6IkpXVCJ9.eyJVc2VySWQiOiIxNTAiLCJVc2VyQ29kZSI6IkRlbW9BZG1pbiIsIlVzZXJOYW1lIjoiRGVtb0FkbWluIiwiVXNlclR5cGUiOiIxIiwiQ29tcGFueUNvZGUiOiIwMDAwMCIsIkZhY3RvcnlDb2RlIjoiMDAwMDAuMDAwMDEiLCJJcCI6IjE5Mi4xNjguODIuMjA0IiwiT3JnYW5pemF0aW9uU3RydWN0dXJlQ29kZSI6IjAwMDAwLjAwMDAxLjAwMDAzIiwiZXhwIjoxNzUyNDU5OTAxLCJpc3MiOiJSaC5NZXMiLCJhdWQiOiJSaC5NZXMuU2VydmljZXMifQ.I_rSySCVpBltpALeaJd4Q1U7AMhTQj9NM_rSggP_3jg'}，请求体: {'OrganizationStructureCode': 'CHANXIANG', 'OrganizationStructureName': '', 'PageSize': 10, 'PageIndex': 1}
ERROR    delete_data:delete_data.py:382 产线数据清理失败: HTTPConnectionPool(host='192.168.0.135', port=8282): Max retries exceeded with url: /ProductionLineApi/GetAllProductionLineAutoQueryDatas (Caused by NewConnectionError('<urllib3.connection.HTTPConnection object at 0x0000026367BDD490>: Failed to establish a new connection: [WinError 10061] 由于目标计算机积极拒绝，无法连接。'))
Traceback (most recent call last):
  File "D:\apiAutomationRH\.venv\Lib\site-packages\urllib3\connection.py", line 198, in _new_conn
    sock = connection.create_connection(
           ^^^^^^^^^^^^^^^^^^^^^^^^^^^^^
  File "D:\apiAutomationRH\.venv\Lib\site-packages\urllib3\util\connection.py", line 85, in create_connection
    raise err
  File "D:\apiAutomationRH\.venv\Lib\site-packages\urllib3\util\connection.py", line 73, in create_connection
    sock.connect(sa)
ConnectionRefusedError: [WinError 10061] 由于目标计算机积极拒绝，无法连接。

The above exception was the direct cause of the following exception:

Traceback (most recent call last):
  File "D:\apiAutomationRH\.venv\Lib\site-packages\urllib3\connectionpool.py", line 787, in urlopen
    response = self._make_request(
               ^^^^^^^^^^^^^^^^^^^
  File "D:\apiAutomationRH\.venv\Lib\site-packages\urllib3\connectionpool.py", line 493, in _make_request
    conn.request(
  File "D:\apiAutomationRH\.venv\Lib\site-packages\urllib3\connection.py", line 494, in request
    self.endheaders()
  File "D:\python\Lib\http\client.py", line 1281, in endheaders
    self._send_output(message_body, encode_chunked=encode_chunked)
  File "D:\python\Lib\http\client.py", line 1041, in _send_output
    self.send(msg)
  File "D:\python\Lib\http\client.py", line 979, in send
    self.connect()
  File "D:\apiAutomationRH\.venv\Lib\site-packages\urllib3\connection.py", line 325, in connect
    self.sock = self._new_conn()
                ^^^^^^^^^^^^^^^^
  File "D:\apiAutomationRH\.venv\Lib\site-packages\urllib3\connection.py", line 213, in _new_conn
    raise NewConnectionError(
urllib3.exceptions.NewConnectionError: <urllib3.connection.HTTPConnection object at 0x0000026367BDD490>: Failed to establish a new connection: [WinError 10061] 由于目标计算机积极拒绝，无法连接。

The above exception was the direct cause of the following exception:

Traceback (most recent call last):
  File "D:\apiAutomationRH\.venv\Lib\site-packages\requests\adapters.py", line 667, in send
    resp = conn.urlopen(
           ^^^^^^^^^^^^^
  File "D:\apiAutomationRH\.venv\Lib\site-packages\urllib3\connectionpool.py", line 841, in urlopen
    retries = retries.increment(
              ^^^^^^^^^^^^^^^^^^
  File "D:\apiAutomationRH\.venv\Lib\site-packages\urllib3\util\retry.py", line 519, in increment
    raise MaxRetryError(_pool, url, reason) from reason  # type: ignore[arg-type]
    ^^^^^^^^^^^^^^^^^^^^^^^^^^^^^^^^^^^^^^^^^^^^^^^^^^^
urllib3.exceptions.MaxRetryError: HTTPConnectionPool(host='192.168.0.135', port=8282): Max retries exceeded with url: /ProductionLineApi/GetAllProductionLineAutoQueryDatas (Caused by NewConnectionError('<urllib3.connection.HTTPConnection object at 0x0000026367BDD490>: Failed to establish a new connection: [WinError 10061] 由于目标计算机积极拒绝，无法连接。'))

During handling of the above exception, another exception occurred:

Traceback (most recent call last):
  File "D:\apiAutomationRH\Toolbox\delete_data.py", line 376, in clean_related_data
    result = delete_func()
             ^^^^^^^^^^^^^
  File "D:\apiAutomationRH\Toolbox\delete_data.py", line 279, in _delete_production_line_data
    query_response = FactoryModel().GetProductionLineAutoQueryDatas()
                     ^^^^^^^^^^^^^^^^^^^^^^^^^^^^^^^^^^^^^^^^^^^^^^^^
  File "D:\apiAutomationRH\Business\mom_admin\production_modeling\factory_model.py", line 164, in GetProductionLineAutoQueryDatas
    raise e
  File "D:\apiAutomationRH\Business\mom_admin\production_modeling\factory_model.py", line 159, in GetProductionLineAutoQueryDatas
    response = requests.post(url=urlGetAllProductionLineAutoQueryDatas, headers=self.headers, json=uploads)
               ^^^^^^^^^^^^^^^^^^^^^^^^^^^^^^^^^^^^^^^^^^^^^^^^^^^^^^^^^^^^^^^^^^^^^^^^^^^^^^^^^^^^^^^^^^^^
  File "D:\apiAutomationRH\.venv\Lib\site-packages\requests\api.py", line 115, in post
    return request("post", url, data=data, json=json, **kwargs)
           ^^^^^^^^^^^^^^^^^^^^^^^^^^^^^^^^^^^^^^^^^^^^^^^^^^^^
  File "D:\apiAutomationRH\.venv\Lib\site-packages\requests\api.py", line 59, in request
    return session.request(method=method, url=url, **kwargs)
           ^^^^^^^^^^^^^^^^^^^^^^^^^^^^^^^^^^^^^^^^^^^^^^^^^
  File "D:\apiAutomationRH\.venv\Lib\site-packages\requests\sessions.py", line 589, in request
    resp = self.send(prep, **send_kwargs)
           ^^^^^^^^^^^^^^^^^^^^^^^^^^^^^^
  File "D:\apiAutomationRH\.venv\Lib\site-packages\requests\sessions.py", line 703, in send
    r = adapter.send(request, **kwargs)
        ^^^^^^^^^^^^^^^^^^^^^^^^^^^^^^^
  File "D:\apiAutomationRH\.venv\Lib\site-packages\requests\adapters.py", line 700, in send
    raise ConnectionError(e, request=request)
requests.exceptions.ConnectionError: HTTPConnectionPool(host='192.168.0.135', port=8282): Max retries exceeded with url: /ProductionLineApi/GetAllProductionLineAutoQueryDatas (Caused by NewConnectionError('<urllib3.connection.HTTPConnection object at 0x0000026367BDD490>: Failed to establish a new connection: [WinError 10061] 由于目标计算机积极拒绝，无法连接。'))
WARNING  get_token:get_token.py:51 Token验证请求失败: HTTPConnectionPool(host='192.168.0.135', port=8282): Max retries exceeded with url: /MaterialInfoApi/GetMaterialInfoAutoQueryDatas (Caused by NewConnectionError('<urllib3.connection.HTTPConnection object at 0x0000026366BD5A10>: Failed to establish a new connection: [WinError 10061] 由于目标计算机积极拒绝，无法连接。'))，但继续使用获取到的token
ERROR    FactoryModel:factory_model.py:69 请求发生错误: HTTPConnectionPool(host='192.168.0.135', port=8282): Max retries exceeded with url: /WorkShopInfoApi/GetAllWorkShopInfoAutoQueryDatas (Caused by NewConnectionError('<urllib3.connection.HTTPConnection object at 0x0000026366AF48D0>: Failed to establish a new connection: [WinError 10061] 由于目标计算机积极拒绝，无法连接。'))，请求 URL: http://192.168.0.135:8282/WorkShopInfoApi/GetAllWorkShopInfoAutoQueryDatas，请求头: {'authorization': 'Bearer eyJhbGciOiJIUzI1NiIsInR5cCI6IkpXVCJ9.eyJVc2VySWQiOiIxNTAiLCJVc2VyQ29kZSI6IkRlbW9BZG1pbiIsIlVzZXJOYW1lIjoiRGVtb0FkbWluIiwiVXNlclR5cGUiOiIxIiwiQ29tcGFueUNvZGUiOiIwMDAwMCIsIkZhY3RvcnlDb2RlIjoiMDAwMDAuMDAwMDEiLCJJcCI6IjE5Mi4xNjguODIuMjA0IiwiT3JnYW5pemF0aW9uU3RydWN0dXJlQ29kZSI6IjAwMDAwLjAwMDAxLjAwMDAzIiwiZXhwIjoxNzUyNDU5OTA1LCJpc3MiOiJSaC5NZXMiLCJhdWQiOiJSaC5NZXMuU2VydmljZXMifQ.N92rulagQKeeq24mXwQoY8V0VKyrNfXL2XzmQce975Q'}，请求体: {'WorkShopInfoCode': 'CHEJIAN', 'IsEnable': True, 'WorkShopInfoName': '自动化车间2', 'IsPaged': True, 'PageSize': 40, 'PageIndex': 1, 'CompanyCode': '00000', 'FactoryCode': '00000.00001'}
ERROR    delete_data:delete_data.py:382 车间数据清理失败: HTTPConnectionPool(host='192.168.0.135', port=8282): Max retries exceeded with url: /WorkShopInfoApi/GetAllWorkShopInfoAutoQueryDatas (Caused by NewConnectionError('<urllib3.connection.HTTPConnection object at 0x0000026366AF48D0>: Failed to establish a new connection: [WinError 10061] 由于目标计算机积极拒绝，无法连接。'))
Traceback (most recent call last):
  File "D:\apiAutomationRH\.venv\Lib\site-packages\urllib3\connection.py", line 198, in _new_conn
    sock = connection.create_connection(
           ^^^^^^^^^^^^^^^^^^^^^^^^^^^^^
  File "D:\apiAutomationRH\.venv\Lib\site-packages\urllib3\util\connection.py", line 85, in create_connection
    raise err
  File "D:\apiAutomationRH\.venv\Lib\site-packages\urllib3\util\connection.py", line 73, in create_connection
    sock.connect(sa)
ConnectionRefusedError: [WinError 10061] 由于目标计算机积极拒绝，无法连接。

The above exception was the direct cause of the following exception:

Traceback (most recent call last):
  File "D:\apiAutomationRH\.venv\Lib\site-packages\urllib3\connectionpool.py", line 787, in urlopen
    response = self._make_request(
               ^^^^^^^^^^^^^^^^^^^
  File "D:\apiAutomationRH\.venv\Lib\site-packages\urllib3\connectionpool.py", line 493, in _make_request
    conn.request(
  File "D:\apiAutomationRH\.venv\Lib\site-packages\urllib3\connection.py", line 494, in request
    self.endheaders()
  File "D:\python\Lib\http\client.py", line 1281, in endheaders
    self._send_output(message_body, encode_chunked=encode_chunked)
  File "D:\python\Lib\http\client.py", line 1041, in _send_output
    self.send(msg)
  File "D:\python\Lib\http\client.py", line 979, in send
    self.connect()
  File "D:\apiAutomationRH\.venv\Lib\site-packages\urllib3\connection.py", line 325, in connect
    self.sock = self._new_conn()
                ^^^^^^^^^^^^^^^^
  File "D:\apiAutomationRH\.venv\Lib\site-packages\urllib3\connection.py", line 213, in _new_conn
    raise NewConnectionError(
urllib3.exceptions.NewConnectionError: <urllib3.connection.HTTPConnection object at 0x0000026366AF48D0>: Failed to establish a new connection: [WinError 10061] 由于目标计算机积极拒绝，无法连接。

The above exception was the direct cause of the following exception:

Traceback (most recent call last):
  File "D:\apiAutomationRH\.venv\Lib\site-packages\requests\adapters.py", line 667, in send
    resp = conn.urlopen(
           ^^^^^^^^^^^^^
  File "D:\apiAutomationRH\.venv\Lib\site-packages\urllib3\connectionpool.py", line 841, in urlopen
    retries = retries.increment(
              ^^^^^^^^^^^^^^^^^^
  File "D:\apiAutomationRH\.venv\Lib\site-packages\urllib3\util\retry.py", line 519, in increment
    raise MaxRetryError(_pool, url, reason) from reason  # type: ignore[arg-type]
    ^^^^^^^^^^^^^^^^^^^^^^^^^^^^^^^^^^^^^^^^^^^^^^^^^^^
urllib3.exceptions.MaxRetryError: HTTPConnectionPool(host='192.168.0.135', port=8282): Max retries exceeded with url: /WorkShopInfoApi/GetAllWorkShopInfoAutoQueryDatas (Caused by NewConnectionError('<urllib3.connection.HTTPConnection object at 0x0000026366AF48D0>: Failed to establish a new connection: [WinError 10061] 由于目标计算机积极拒绝，无法连接。'))

During handling of the above exception, another exception occurred:

Traceback (most recent call last):
  File "D:\apiAutomationRH\Toolbox\delete_data.py", line 376, in clean_related_data
    result = delete_func()
             ^^^^^^^^^^^^^
  File "D:\apiAutomationRH\Toolbox\delete_data.py", line 311, in _delete_workshop_data
    query_response = FactoryModel().GetWorkshopAutoQueryDatas()
                     ^^^^^^^^^^^^^^^^^^^^^^^^^^^^^^^^^^^^^^^^^^
  File "D:\apiAutomationRH\Business\mom_admin\production_modeling\factory_model.py", line 70, in GetWorkshopAutoQueryDatas
    raise e
  File "D:\apiAutomationRH\Business\mom_admin\production_modeling\factory_model.py", line 65, in GetWorkshopAutoQueryDatas
    response = requests.post(url=urlGetAllWorkShopInfoAutoQueryDatas, headers=self.headers, json=uploads)
               ^^^^^^^^^^^^^^^^^^^^^^^^^^^^^^^^^^^^^^^^^^^^^^^^^^^^^^^^^^^^^^^^^^^^^^^^^^^^^^^^^^^^^^^^^^
  File "D:\apiAutomationRH\.venv\Lib\site-packages\requests\api.py", line 115, in post
    return request("post", url, data=data, json=json, **kwargs)
           ^^^^^^^^^^^^^^^^^^^^^^^^^^^^^^^^^^^^^^^^^^^^^^^^^^^^
  File "D:\apiAutomationRH\.venv\Lib\site-packages\requests\api.py", line 59, in request
    return session.request(method=method, url=url, **kwargs)
           ^^^^^^^^^^^^^^^^^^^^^^^^^^^^^^^^^^^^^^^^^^^^^^^^^
  File "D:\apiAutomationRH\.venv\Lib\site-packages\requests\sessions.py", line 589, in request
    resp = self.send(prep, **send_kwargs)
           ^^^^^^^^^^^^^^^^^^^^^^^^^^^^^^
  File "D:\apiAutomationRH\.venv\Lib\site-packages\requests\sessions.py", line 703, in send
    r = adapter.send(request, **kwargs)
        ^^^^^^^^^^^^^^^^^^^^^^^^^^^^^^^
  File "D:\apiAutomationRH\.venv\Lib\site-packages\requests\adapters.py", line 700, in send
    raise ConnectionError(e, request=request)
requests.exceptions.ConnectionError: HTTPConnectionPool(host='192.168.0.135', port=8282): Max retries exceeded with url: /WorkShopInfoApi/GetAllWorkShopInfoAutoQueryDatas (Caused by NewConnectionError('<urllib3.connection.HTTPConnection object at 0x0000026366AF48D0>: Failed to establish a new connection: [WinError 10061] 由于目标计算机积极拒绝，无法连接。'))
INFO     mainprocess_tests:test_mainprocess.py:42 前置条件：批量删除接口调用成功，测试数据已清理
WARNING  get_token:get_token.py:51 Token验证请求失败: HTTPConnectionPool(host='192.168.0.135', port=8282): Max retries exceeded with url: /MaterialInfoApi/GetMaterialInfoAutoQueryDatas (Caused by NewConnectionError('<urllib3.connection.HTTPConnection object at 0x0000026367C617D0>: Failed to establish a new connection: [WinError 10061] 由于目标计算机积极拒绝，无法连接。'))，但继续使用获取到的token
WARNING  get_token:get_token.py:51 Token验证请求失败: HTTPConnectionPool(host='192.168.0.135', port=8282): Max retries exceeded with url: /MaterialInfoApi/GetMaterialInfoAutoQueryDatas (Caused by NewConnectionError('<urllib3.connection.HTTPConnection object at 0x0000026367C69F50>: Failed to establish a new connection: [WinError 10061] 由于目标计算机积极拒绝，无法连接。'))，但继续使用获取到的token
WARNING  get_token:get_token.py:51 Token验证请求失败: HTTPConnectionPool(host='192.168.0.135', port=8282): Max retries exceeded with url: /MaterialInfoApi/GetMaterialInfoAutoQueryDatas (Caused by NewConnectionError('<urllib3.connection.HTTPConnection object at 0x0000026366BC1810>: Failed to establish a new connection: [WinError 10061] 由于目标计算机积极拒绝，无法连接。'))，但继续使用获取到的token
WARNING  get_token:get_token.py:51 Token验证请求失败: HTTPConnectionPool(host='192.168.0.135', port=8282): Max retries exceeded with url: /MaterialInfoApi/GetMaterialInfoAutoQueryDatas (Caused by NewConnectionError('<urllib3.connection.HTTPConnection object at 0x0000026367C6B090>: Failed to establish a new connection: [WinError 10061] 由于目标计算机积极拒绝，无法连接。'))，但继续使用获取到的token
WARNING  get_token:get_token.py:51 Token验证请求失败: HTTPConnectionPool(host='192.168.0.135', port=8282): Max retries exceeded with url: /MaterialInfoApi/GetMaterialInfoAutoQueryDatas (Caused by NewConnectionError('<urllib3.connection.HTTPConnection object at 0x0000026367C737D0>: Failed to establish a new connection: [WinError 10061] 由于目标计算机积极拒绝，无法连接。'))，但继续使用获取到的token
WARNING  get_token:get_token.py:51 Token验证请求失败: HTTPConnectionPool(host='192.168.0.135', port=8282): Max retries exceeded with url: /MaterialInfoApi/GetMaterialInfoAutoQueryDatas (Caused by NewConnectionError('<urllib3.connection.HTTPConnection object at 0x0000026367C2F290>: Failed to establish a new connection: [WinError 10061] 由于目标计算机积极拒绝，无法连接。'))，但继续使用获取到的token
WARNING  get_token:get_token.py:51 Token验证请求失败: HTTPConnectionPool(host='192.168.0.135', port=8282): Max retries exceeded with url: /MaterialInfoApi/GetMaterialInfoAutoQueryDatas (Caused by NewConnectionError('<urllib3.connection.HTTPConnection object at 0x0000026367C7C8D0>: Failed to establish a new connection: [WinError 10061] 由于目标计算机积极拒绝，无法连接。'))，但继续使用获取到的token
WARNING  get_token:get_token.py:51 Token验证请求失败: HTTPConnectionPool(host='192.168.0.135', port=8282): Max retries exceeded with url: /MaterialInfoApi/GetMaterialInfoAutoQueryDatas (Caused by NewConnectionError('<urllib3.connection.HTTPConnection object at 0x0000026367C80F50>: Failed to establish a new connection: [WinError 10061] 由于目标计算机积极拒绝，无法连接。'))，但继续使用获取到的token
WARNING  get_token:get_token.py:51 Token验证请求失败: HTTPConnectionPool(host='192.168.0.135', port=8282): Max retries exceeded with url: /MaterialInfoApi/GetMaterialInfoAutoQueryDatas (Caused by NewConnectionError('<urllib3.connection.HTTPConnection object at 0x0000026367BD7710>: Failed to establish a new connection: [WinError 10061] 由于目标计算机积极拒绝，无法连接。'))，但继续使用获取到的token
WARNING  get_token:get_token.py:51 Token验证请求失败: HTTPConnectionPool(host='192.168.0.135', port=8282): Max retries exceeded with url: /MaterialInfoApi/GetMaterialInfoAutoQueryDatas (Caused by NewConnectionError('<urllib3.connection.HTTPConnection object at 0x0000026367C82090>: Failed to establish a new connection: [WinError 10061] 由于目标计算机积极拒绝，无法连接。'))，但继续使用获取到的token
WARNING  get_token:get_token.py:51 Token验证请求失败: HTTPConnectionPool(host='192.168.0.135', port=8282): Max retries exceeded with url: /MaterialInfoApi/GetMaterialInfoAutoQueryDatas (Caused by NewConnectionError('<urllib3.connection.HTTPConnection object at 0x0000026367C8A750>: Failed to establish a new connection: [WinError 10061] 由于目标计算机积极拒绝，无法连接。'))，但继续使用获取到的token
ERROR    ProductMaterials:product_materials.py:79 请求发生错误: HTTPConnectionPool(host='192.168.0.135', port=8282): Max retries exceeded with url: /MaterialInfoApi/StoreMaterialInfoData (Caused by NewConnectionError('<urllib3.connection.HTTPConnection object at 0x0000026367BD4DD0>: Failed to establish a new connection: [WinError 10061] 由于目标计算机积极拒绝，无法连接。'))，请求 URL: http://192.168.0.135:8282/MaterialInfoApi/StoreMaterialInfoData，请求头: {'authorization': 'Bearer eyJhbGciOiJIUzI1NiIsInR5cCI6IkpXVCJ9.eyJVc2VySWQiOiIxNTAiLCJVc2VyQ29kZSI6IkRlbW9BZG1pbiIsIlVzZXJOYW1lIjoiRGVtb0FkbWluIiwiVXNlclR5cGUiOiIxIiwiQ29tcGFueUNvZGUiOiIwMDAwMCIsIkZhY3RvcnlDb2RlIjoiMDAwMDAuMDAwMDEiLCJJcCI6IjE5Mi4xNjguODIuMjA0IiwiT3JnYW5pemF0aW9uU3RydWN0dXJlQ29kZSI6IjAwMDAwLjAwMDAxLjAwMDAzIiwiZXhwIjoxNzUyNDU5OTE1LCJpc3MiOiJSaC5NZXMiLCJhdWQiOiJSaC5NZXMuU2VydmljZXMifQ.MN4rWGzqN8MvEce6QggdHVfK5S1n54GrnS07ShqJNi0'}，请求体: {'MaterialCode': 'Automation01', 'MaterialName': '自动化测试物料01', 'materialCharacteristic': [{'label': '成品', 'value': 'IsProduct', 'customData': {'checked': True}, 'checked': True}, {'label': '半成品', 'value': 'IsSemiFinishedProduct', 'customData': {'checked': True}, 'checked': True}, {'label': '物料', 'value': 'IsMaterial', 'customData': {'checked': True}, 'checked': True}], 'MaterialCategoryCode': 'DQJ', 'MaterialAttribute': 'SelfCreated', 'MaterialSpecification': '', 'MaterialDrawCode': None, 'MaterialUnit': None, 'MaterialAuxUnit': None, 'MaterialVersion': '', 'DataSource': '', 'IsUse': True, 'IsChecked': False, 'Remark': '', 'OpSign': 1, 'MaintainerId': 10402, 'MaintainerName': 'CQ', 'MaintainTime': '2025-06-25T06:07:33.626Z', 'IsProduct': True, 'IsSemiFinishedProduct': True, 'IsMaterial': True, 'CompanyCode': '00000', 'FactoryCode': '00000.00001'}
ERROR    mainprocess_tests:test_mainprocess.py:113 新增物料失败：storeMaterialInfoData接口返回None，请检查接口或依赖服务是否正常
assert None is not None